<mujoco model="tendon-finger">
<!-- =================================================
	Copyright 2020 Vikash Kumar
	Model	:: tendon-finger (MuJoCoV2.0)
	Author	:: Vikash Kumar (vikashplus@gmail.com)
	source	:: https://github.com/vikashplus
	License	:: Under Apache License, Version 2.0 (the "License"); you may not use this file except in compliance with the License. You may obtain a copy of the License at http://www.apache.org/licenses/LICENSE-2.0 Unless required by applicable law or agreed to in writing, software distributed under the License is distributed on an "AS IS" BASIS, WITHOUT WARRANTIES OR CONDITIONS OF ANY KIND, either express or implied. See the License for the specific language governing permissions and limitations under the License.
====================================================== -->

	<default>
		<geom rgba=".9 .8 .6 1" size="0.01"/>
		<site type="sphere" rgba=".9 .9 .9 1" size="0.005"/>
		<joint type="hinge" axis="0 1 0" damping=".1" armature="0.01" limited="true" range="0 60" solimplimit="0.95 0.95 0.1"/>
		<default class="muscle">
			<muscle ctrllimited="true" ctrlrange="0 1" scale="10000"></muscle>
		</default>
	</default>

	<visual>
		<headlight diffuse=".9 .9 .9"/>
	</visual>

	<worldbody>
		<geom type="plane" size="1 1 1" rgba=".2 .3 .2 1"/>

		<!-- BASE -->
		<site name="bs3" pos="-0.02 0.00 0.33"/>

		<!-- link -->
		<body name="proximal">
			<geom type="capsule" fromto="0 0 0.3 0.1 0 0.3" size=".018"/>
			<geom name="pg1" type="sphere" pos="0.0 0.0 0.3" size="0.024" rgba=".5 .5 .9 .4"/>
			<joint name="IFmcp" pos="0 0 0.3" axis="0 1 0" range="-25 60"/>
			<site name="ps3" pos="0.035 0.00 0.32"/>
		</body>
	</worldbody>

	<tendon>
		<spatial name="extn" width="0.002" rgba=".95 .3 .3 1" limited="true" range="0 0.33">
			<site site="bs3"/>
			<geom geom="pg1"/>
			<site site="ps3"/>
		</spatial>
	</tendon>
</mujoco>